{\rtf1\ansi\ansicpg1252\cocoartf1671\cocoasubrtf600
{\fonttbl\f0\fnil\fcharset0 Menlo-Regular;}
{\colortbl;\red255\green255\blue255;}
{\*\expandedcolortbl;;}
\paperw11900\paperh16840\margl1440\margr1440\vieww22260\viewh14920\viewkind0
\pard\tx566\tx1133\tx1700\tx2267\tx2834\tx3401\tx3968\tx4535\tx5102\tx5669\tx6236\tx6803\pardirnatural\partightenfactor0

\f0\fs28 \cf0 >>> for process in processes:\
...     process.join()\
... \
Process Process-8:\
Traceback (most recent call last):\
  File "/Library/Frameworks/Python.framework/Versions/3.7/lib/python3.7/multiprocessing/process.py", line 297, in _bootstrap\
    self.run()\
  File "/Library/Frameworks/Python.framework/Versions/3.7/lib/python3.7/multiprocessing/process.py", line 99, in run\
    self._target(*self._args, **self._kwargs)\
  File "<stdin>", line 4, in scrap_entire_webpage\
  File "<stdin>", line 3, in loop_all_aparts\
  File "/Library/Frameworks/Python.framework/Versions/3.7/lib/python3.7/site-packages/selenium/webdriver/remote/webdriver.py", line 636, in execute_script\
    'args': converted_args\})['value']\
  File "/Library/Frameworks/Python.framework/Versions/3.7/lib/python3.7/site-packages/selenium/webdriver/remote/webdriver.py", line 321, in execute\
    self.error_handler.check_response(response)\
  File "/Library/Frameworks/Python.framework/Versions/3.7/lib/python3.7/site-packages/selenium/webdriver/remote/errorhandler.py", line 242, in check_response\
    raise exception_class(message, screen, stacktrace)\
selenium.common.exceptions.StaleElementReferenceException: Message: stale element reference: element is not attached to the page document\
  (Session info: chrome=78.0.3904.70)\
\
Process Process-2:\
Traceback (most recent call last):\
  File "/Library/Frameworks/Python.framework/Versions/3.7/lib/python3.7/multiprocessing/process.py", line 297, in _bootstrap\
    self.run()\
  File "/Library/Frameworks/Python.framework/Versions/3.7/lib/python3.7/multiprocessing/process.py", line 99, in run\
    self._target(*self._args, **self._kwargs)\
  File "<stdin>", line 4, in scrap_entire_webpage\
  File "<stdin>", line 3, in loop_all_aparts\
  File "/Library/Frameworks/Python.framework/Versions/3.7/lib/python3.7/site-packages/selenium/webdriver/remote/webdriver.py", line 636, in execute_script\
    'args': converted_args\})['value']\
  File "/Library/Frameworks/Python.framework/Versions/3.7/lib/python3.7/site-packages/selenium/webdriver/remote/webdriver.py", line 321, in execute\
    self.error_handler.check_response(response)\
  File "/Library/Frameworks/Python.framework/Versions/3.7/lib/python3.7/site-packages/selenium/webdriver/remote/errorhandler.py", line 242, in check_response\
    raise exception_class(message, screen, stacktrace)\
selenium.common.exceptions.StaleElementReferenceException: Message: stale element reference: element is not attached to the page document\
  (Session info: chrome=78.0.3904.70)\
\
Process Process-11:\
Traceback (most recent call last):\
  File "/Library/Frameworks/Python.framework/Versions/3.7/lib/python3.7/multiprocessing/process.py", line 297, in _bootstrap\
    self.run()\
  File "/Library/Frameworks/Python.framework/Versions/3.7/lib/python3.7/multiprocessing/process.py", line 99, in run\
    self._target(*self._args, **self._kwargs)\
  File "<stdin>", line 4, in scrap_entire_webpage\
  File "<stdin>", line 4, in loop_all_aparts\
  File "/Users/macbookpro_anas/Desktop/Machine-learning/scrapper_immo/soup_parsing.py", line 73, in scrap_one_ad\
    data_list = get_data_form_html(browser)\
  File "/Users/macbookpro_anas/Desktop/Machine-learning/scrapper_immo/soup_parsing.py", line 37, in get_data_form_html\
    WebDriverWait(driver,10).until(EC.presence_of_element_located((By.ID, "iw-propertypage-verticals")))\
  File "/Library/Frameworks/Python.framework/Versions/3.7/lib/python3.7/site-packages/selenium/webdriver/support/wait.py", line 71, in until\
    value = method(self._driver)\
  File "/Library/Frameworks/Python.framework/Versions/3.7/lib/python3.7/site-packages/selenium/webdriver/support/expected_conditions.py", line 64, in __call__\
    return _find_element(driver, self.locator)\
  File "/Library/Frameworks/Python.framework/Versions/3.7/lib/python3.7/site-packages/selenium/webdriver/support/expected_conditions.py", line 415, in _find_element\
    raise e\
  File "/Library/Frameworks/Python.framework/Versions/3.7/lib/python3.7/site-packages/selenium/webdriver/support/expected_conditions.py", line 411, in _find_element\
    return driver.find_element(*by)\
  File "/Library/Frameworks/Python.framework/Versions/3.7/lib/python3.7/site-packages/selenium/webdriver/remote/webdriver.py", line 978, in find_element\
    'value': value\})['value']\
  File "/Library/Frameworks/Python.framework/Versions/3.7/lib/python3.7/site-packages/selenium/webdriver/remote/webdriver.py", line 321, in execute\
    self.error_handler.check_response(response)\
  File "/Library/Frameworks/Python.framework/Versions/3.7/lib/python3.7/site-packages/selenium/webdriver/remote/errorhandler.py", line 242, in check_response\
    raise exception_class(message, screen, stacktrace)\
selenium.common.exceptions.StaleElementReferenceException: Message: stale element reference: element is not attached to the page document\
  (Session info: chrome=78.0.3904.70)\
\
Process Process-3:\
Traceback (most recent call last):\
  File "/Library/Frameworks/Python.framework/Versions/3.7/lib/python3.7/multiprocessing/process.py", line 297, in _bootstrap\
    self.run()\
  File "/Library/Frameworks/Python.framework/Versions/3.7/lib/python3.7/multiprocessing/process.py", line 99, in run\
    self._target(*self._args, **self._kwargs)\
  File "<stdin>", line 3, in scrap_entire_webpage\
  File "/Library/Frameworks/Python.framework/Versions/3.7/lib/python3.7/site-packages/selenium/webdriver/remote/webdriver.py", line 580, in find_elements_by_class_name\
    return self.find_elements(by=By.CLASS_NAME, value=name)\
  File "/Library/Frameworks/Python.framework/Versions/3.7/lib/python3.7/site-packages/selenium/webdriver/remote/webdriver.py", line 1007, in find_elements\
    'value': value\})['value'] or []\
  File "/Library/Frameworks/Python.framework/Versions/3.7/lib/python3.7/site-packages/selenium/webdriver/remote/webdriver.py", line 321, in execute\
    self.error_handler.check_response(response)\
  File "/Library/Frameworks/Python.framework/Versions/3.7/lib/python3.7/site-packages/selenium/webdriver/remote/errorhandler.py", line 242, in check_response\
    raise exception_class(message, screen, stacktrace)\
selenium.common.exceptions.StaleElementReferenceException: Message: stale element reference: element is not attached to the page document\
  (Session info: chrome=78.0.3904.70)\
\
Process Process-10:\
Traceback (most recent call last):\
  File "/Library/Frameworks/Python.framework/Versions/3.7/lib/python3.7/multiprocessing/process.py", line 297, in _bootstrap\
    self.run()\
  File "/Library/Frameworks/Python.framework/Versions/3.7/lib/python3.7/multiprocessing/process.py", line 99, in run\
    self._target(*self._args, **self._kwargs)\
  File "<stdin>", line 3, in scrap_entire_webpage\
  File "/Library/Frameworks/Python.framework/Versions/3.7/lib/python3.7/site-packages/selenium/webdriver/remote/webdriver.py", line 580, in find_elements_by_class_name\
    return self.find_elements(by=By.CLASS_NAME, value=name)\
  File "/Library/Frameworks/Python.framework/Versions/3.7/lib/python3.7/site-packages/selenium/webdriver/remote/webdriver.py", line 1007, in find_elements\
    'value': value\})['value'] or []\
  File "/Library/Frameworks/Python.framework/Versions/3.7/lib/python3.7/site-packages/selenium/webdriver/remote/webdriver.py", line 321, in execute\
    self.error_handler.check_response(response)\
  File "/Library/Frameworks/Python.framework/Versions/3.7/lib/python3.7/site-packages/selenium/webdriver/remote/errorhandler.py", line 242, in check_response\
    raise exception_class(message, screen, stacktrace)\
selenium.common.exceptions.StaleElementReferenceException: Message: stale element reference: element is not attached to the page document\
  (Session info: chrome=78.0.3904.70)\
\
Process Process-9:\
Traceback (most recent call last):\
  File "/Library/Frameworks/Python.framework/Versions/3.7/lib/python3.7/site-packages/urllib3/connectionpool.py", line 672, in urlopen\
    chunked=chunked,\
  File "/Library/Frameworks/Python.framework/Versions/3.7/lib/python3.7/site-packages/urllib3/connectionpool.py", line 421, in _make_request\
    six.raise_from(e, None)\
  File "<string>", line 3, in raise_from\
  File "/Library/Frameworks/Python.framework/Versions/3.7/lib/python3.7/site-packages/urllib3/connectionpool.py", line 416, in _make_request\
    httplib_response = conn.getresponse()\
  File "/Library/Frameworks/Python.framework/Versions/3.7/lib/python3.7/http/client.py", line 1321, in getresponse\
    response.begin()\
  File "/Library/Frameworks/Python.framework/Versions/3.7/lib/python3.7/http/client.py", line 296, in begin\
    version, status, reason = self._read_status()\
  File "/Library/Frameworks/Python.framework/Versions/3.7/lib/python3.7/http/client.py", line 259, in _read_status\
    raise LineTooLong("status line")\
http.client.LineTooLong: got more than 65536 bytes when reading status line\
\
During handling of the above exception, another exception occurred:\
\
Traceback (most recent call last):\
  File "/Library/Frameworks/Python.framework/Versions/3.7/lib/python3.7/multiprocessing/process.py", line 297, in _bootstrap\
    self.run()\
  File "/Library/Frameworks/Python.framework/Versions/3.7/lib/python3.7/multiprocessing/process.py", line 99, in run\
    self._target(*self._args, **self._kwargs)\
  File "<stdin>", line 4, in scrap_entire_webpage\
  File "<stdin>", line 4, in loop_all_aparts\
  File "/Users/macbookpro_anas/Desktop/Machine-learning/scrapper_immo/soup_parsing.py", line 73, in scrap_one_ad\
    data_list = get_data_form_html(browser)\
  File "/Users/macbookpro_anas/Desktop/Machine-learning/scrapper_immo/soup_parsing.py", line 37, in get_data_form_html\
    WebDriverWait(driver,10).until(EC.presence_of_element_located((By.ID, "iw-propertypage-verticals")))\
  File "/Library/Frameworks/Python.framework/Versions/3.7/lib/python3.7/site-packages/selenium/webdriver/support/wait.py", line 71, in until\
    value = method(self._driver)\
  File "/Library/Frameworks/Python.framework/Versions/3.7/lib/python3.7/site-packages/selenium/webdriver/support/expected_conditions.py", line 64, in __call__\
    return _find_element(driver, self.locator)\
  File "/Library/Frameworks/Python.framework/Versions/3.7/lib/python3.7/site-packages/selenium/webdriver/support/expected_conditions.py", line 411, in _find_element\
    return driver.find_element(*by)\
  File "/Library/Frameworks/Python.framework/Versions/3.7/lib/python3.7/site-packages/selenium/webdriver/remote/webdriver.py", line 978, in find_element\
    'value': value\})['value']\
  File "/Library/Frameworks/Python.framework/Versions/3.7/lib/python3.7/site-packages/selenium/webdriver/remote/webdriver.py", line 319, in execute\
    response = self.command_executor.execute(driver_command, params)\
  File "/Library/Frameworks/Python.framework/Versions/3.7/lib/python3.7/site-packages/selenium/webdriver/remote/remote_connection.py", line 374, in execute\
    return self._request(command_info[0], url, body=data)\
  File "/Library/Frameworks/Python.framework/Versions/3.7/lib/python3.7/site-packages/selenium/webdriver/remote/remote_connection.py", line 397, in _request\
    resp = self._conn.request(method, url, body=body, headers=headers)\
  File "/Library/Frameworks/Python.framework/Versions/3.7/lib/python3.7/site-packages/urllib3/request.py", line 80, in request\
    method, url, fields=fields, headers=headers, **urlopen_kw\
  File "/Library/Frameworks/Python.framework/Versions/3.7/lib/python3.7/site-packages/urllib3/request.py", line 171, in request_encode_body\
    return self.urlopen(method, url, **extra_kw)\
  File "/Library/Frameworks/Python.framework/Versions/3.7/lib/python3.7/site-packages/urllib3/poolmanager.py", line 330, in urlopen\
    response = conn.urlopen(method, u.request_uri, **kw)\
  File "/Library/Frameworks/Python.framework/Versions/3.7/lib/python3.7/site-packages/urllib3/connectionpool.py", line 720, in urlopen\
    method, url, error=e, _pool=self, _stacktrace=sys.exc_info()[2]\
  File "/Library/Frameworks/Python.framework/Versions/3.7/lib/python3.7/site-packages/urllib3/util/retry.py", line 400, in increment\
    raise six.reraise(type(error), error, _stacktrace)\
  File "/Library/Frameworks/Python.framework/Versions/3.7/lib/python3.7/site-packages/urllib3/packages/six.py", line 734, in reraise\
    raise value.with_traceback(tb)\
  File "/Library/Frameworks/Python.framework/Versions/3.7/lib/python3.7/site-packages/urllib3/connectionpool.py", line 672, in urlopen\
    chunked=chunked,\
  File "/Library/Frameworks/Python.framework/Versions/3.7/lib/python3.7/site-packages/urllib3/connectionpool.py", line 421, in _make_request\
    six.raise_from(e, None)\
  File "<string>", line 3, in raise_from\
  File "/Library/Frameworks/Python.framework/Versions/3.7/lib/python3.7/site-packages/urllib3/connectionpool.py", line 416, in _make_request\
    httplib_response = conn.getresponse()\
  File "/Library/Frameworks/Python.framework/Versions/3.7/lib/python3.7/http/client.py", line 1321, in getresponse\
    response.begin()\
  File "/Library/Frameworks/Python.framework/Versions/3.7/lib/python3.7/http/client.py", line 296, in begin\
    version, status, reason = self._read_status()\
  File "/Library/Frameworks/Python.framework/Versions/3.7/lib/python3.7/http/client.py", line 259, in _read_status\
    raise LineTooLong("status line")\
urllib3.exceptions.ProtocolError: ('Connection aborted.', LineTooLong('got more than 65536 bytes when reading status line'))\
}